WARNING:__main__:
*****************************************
Setting OMP_NUM_THREADS environment variable for each process to be 1 in default, to avoid your system being overloaded, please further tune the variable for optimal performance in your application as needed. 
*****************************************
Traceback (most recent call last):
  File "/work/cvcs_2023_group23/ObjectDescriptionSupermarket-CVCS-UniMoRe/train.py", line 356, in <module>
Traceback (most recent call last):
  File "/work/cvcs_2023_group23/ObjectDescriptionSupermarket-CVCS-UniMoRe/train.py", line 356, in <module>
    main()
      File "/work/cvcs_2023_group23/ObjectDescriptionSupermarket-CVCS-UniMoRe/train.py", line 280, in main
main()Traceback (most recent call last):
  File "/work/cvcs_2023_group23/ObjectDescriptionSupermarket-CVCS-UniMoRe/train.py", line 356, in <module>

      File "/work/cvcs_2023_group23/ObjectDescriptionSupermarket-CVCS-UniMoRe/train.py", line 280, in main
model = get_model(args.model, 2)
      File "/work/cvcs_2023_group23/ObjectDescriptionSupermarket-CVCS-UniMoRe/train.py", line 76, in get_model
main()    
model = get_model(args.model, 2)  File "/work/cvcs_2023_group23/ObjectDescriptionSupermarket-CVCS-UniMoRe/train.py", line 280, in main
    
model = fasterrcnn_resnet50_fpn(pretrained=True)
  File "/work/cvcs_2023_group23/ObjectDescriptionSupermarket-CVCS-UniMoRe/train.py", line 76, in get_model
    NameErrormodel = get_model(args.model, 2): 
name 'fasterrcnn_resnet50_fpn' is not defined
      File "/work/cvcs_2023_group23/ObjectDescriptionSupermarket-CVCS-UniMoRe/train.py", line 76, in get_model
model = fasterrcnn_resnet50_fpn(pretrained=True)
NameError: name 'fasterrcnn_resnet50_fpn' is not defined    model = fasterrcnn_resnet50_fpn(pretrained=True)

NameError: name 'fasterrcnn_resnet50_fpn' is not defined
ERROR:torch.distributed.elastic.multiprocessing.api:failed (exitcode: 1) local_rank: 0 (pid: 3604341) of binary: /work/cvcs_2023_group23/environments/cvcs_env/bin/python
Traceback (most recent call last):
  File "/usr/local/anaconda3/lib/python3.9/runpy.py", line 197, in _run_module_as_main
    return _run_code(code, main_globals, None,
  File "/usr/local/anaconda3/lib/python3.9/runpy.py", line 87, in _run_code
    exec(code, run_globals)
  File "/work/cvcs_2023_group23/environments/cvcs_env/lib/python3.9/site-packages/torch/distributed/run.py", line 798, in <module>
    main()
  File "/work/cvcs_2023_group23/environments/cvcs_env/lib/python3.9/site-packages/torch/distributed/elastic/multiprocessing/errors/__init__.py", line 346, in wrapper
    return f(*args, **kwargs)
  File "/work/cvcs_2023_group23/environments/cvcs_env/lib/python3.9/site-packages/torch/distributed/run.py", line 794, in main
    run(args)
  File "/work/cvcs_2023_group23/environments/cvcs_env/lib/python3.9/site-packages/torch/distributed/run.py", line 785, in run
    elastic_launch(
  File "/work/cvcs_2023_group23/environments/cvcs_env/lib/python3.9/site-packages/torch/distributed/launcher/api.py", line 134, in __call__
    return launch_agent(self._config, self._entrypoint, list(args))
  File "/work/cvcs_2023_group23/environments/cvcs_env/lib/python3.9/site-packages/torch/distributed/launcher/api.py", line 250, in launch_agent
    raise ChildFailedError(
torch.distributed.elastic.multiprocessing.errors.ChildFailedError: 
============================================================
train.py FAILED
------------------------------------------------------------
Failures:
[1]:
  time      : 2024-01-20_20:36:28
  host      : aimagelab-srv-00.ing.unimore.it
  rank      : 1 (local_rank: 1)
  exitcode  : 1 (pid: 3604342)
  error_file: <N/A>
  traceback : To enable traceback see: https://pytorch.org/docs/stable/elastic/errors.html
[2]:
  time      : 2024-01-20_20:36:28
  host      : aimagelab-srv-00.ing.unimore.it
  rank      : 2 (local_rank: 2)
  exitcode  : 1 (pid: 3604343)
  error_file: <N/A>
  traceback : To enable traceback see: https://pytorch.org/docs/stable/elastic/errors.html
------------------------------------------------------------
Root Cause (first observed failure):
[0]:
  time      : 2024-01-20_20:36:28
  host      : aimagelab-srv-00.ing.unimore.it
  rank      : 0 (local_rank: 0)
  exitcode  : 1 (pid: 3604341)
  error_file: <N/A>
  traceback : To enable traceback see: https://pytorch.org/docs/stable/elastic/errors.html
============================================================
WARNING:__main__:
*****************************************
Setting OMP_NUM_THREADS environment variable for each process to be 1 in default, to avoid your system being overloaded, please further tune the variable for optimal performance in your application as needed. 
*****************************************
/work/cvcs_2023_group23/environments/cvcs_env/lib/python3.9/site-packages/torchvision/models/_utils.py:208: UserWarning: The parameter 'pretrained' is deprecated since 0.13 and may be removed in the future, please use 'weights' instead.
  warnings.warn(
/work/cvcs_2023_group23/environments/cvcs_env/lib/python3.9/site-packages/torchvision/models/_utils.py:223: UserWarning: Arguments other than a weight enum or `None` for 'weights' are deprecated since 0.13 and may be removed in the future. The current behavior is equivalent to passing `weights=FasterRCNN_ResNet50_FPN_Weights.COCO_V1`. You can also use `weights=FasterRCNN_ResNet50_FPN_Weights.DEFAULT` to get the most up-to-date weights.
  warnings.warn(msg)
/work/cvcs_2023_group23/environments/cvcs_env/lib/python3.9/site-packages/torchvision/models/_utils.py:208: UserWarning: The parameter 'pretrained' is deprecated since 0.13 and may be removed in the future, please use 'weights' instead.
  warnings.warn(
/work/cvcs_2023_group23/environments/cvcs_env/lib/python3.9/site-packages/torchvision/models/_utils.py:223: UserWarning: Arguments other than a weight enum or `None` for 'weights' are deprecated since 0.13 and may be removed in the future. The current behavior is equivalent to passing `weights=FasterRCNN_ResNet50_FPN_Weights.COCO_V1`. You can also use `weights=FasterRCNN_ResNet50_FPN_Weights.DEFAULT` to get the most up-to-date weights.
  warnings.warn(msg)
/work/cvcs_2023_group23/environments/cvcs_env/lib/python3.9/site-packages/torchvision/models/_utils.py:208: UserWarning: The parameter 'pretrained' is deprecated since 0.13 and may be removed in the future, please use 'weights' instead.
  warnings.warn(
/work/cvcs_2023_group23/environments/cvcs_env/lib/python3.9/site-packages/torchvision/models/_utils.py:223: UserWarning: Arguments other than a weight enum or `None` for 'weights' are deprecated since 0.13 and may be removed in the future. The current behavior is equivalent to passing `weights=FasterRCNN_ResNet50_FPN_Weights.COCO_V1`. You can also use `weights=FasterRCNN_ResNet50_FPN_Weights.DEFAULT` to get the most up-to-date weights.
  warnings.warn(msg)
Traceback (most recent call last):
  File "/work/cvcs_2023_group23/ObjectDescriptionSupermarket-CVCS-UniMoRe/evaluate.py", line 318, in <module>
    main()
  File "/work/cvcs_2023_group23/ObjectDescriptionSupermarket-CVCS-UniMoRe/evaluate.py", line 297, in main
    model = load_model(
  File "/work/cvcs_2023_group23/ObjectDescriptionSupermarket-CVCS-UniMoRe/evaluate.py", line 76, in load_model
    checkpoint = torch.load(checkpoint_path)
  File "/work/cvcs_2023_group23/environments/cvcs_env/lib/python3.9/site-packages/torch/serialization.py", line 791, in load
    with _open_file_like(f, 'rb') as opened_file:
  File "/work/cvcs_2023_group23/environments/cvcs_env/lib/python3.9/site-packages/torch/serialization.py", line 271, in _open_file_like
    return _open_file(name_or_buffer, mode)
  File "/work/cvcs_2023_group23/environments/cvcs_env/lib/python3.9/site-packages/torch/serialization.py", line 252, in __init__
    super().__init__(open(name, mode))
FileNotFoundError: [Errno 2] No such file or directory: '/work/cvcs_2023_group23/ObjectDescriptionSupermarket-CVCS-UniMoRe/checkpoints/frcnn/checkpoint.pth'
Traceback (most recent call last):
  File "/work/cvcs_2023_group23/ObjectDescriptionSupermarket-CVCS-UniMoRe/evaluate.py", line 318, in <module>
    main()
  File "/work/cvcs_2023_group23/ObjectDescriptionSupermarket-CVCS-UniMoRe/evaluate.py", line 297, in main
    model = load_model(
  File "/work/cvcs_2023_group23/ObjectDescriptionSupermarket-CVCS-UniMoRe/evaluate.py", line 76, in load_model
    checkpoint = torch.load(checkpoint_path)
  File "/work/cvcs_2023_group23/environments/cvcs_env/lib/python3.9/site-packages/torch/serialization.py", line 791, in load
    with _open_file_like(f, 'rb') as opened_file:
  File "/work/cvcs_2023_group23/environments/cvcs_env/lib/python3.9/site-packages/torch/serialization.py", line 271, in _open_file_like
    return _open_file(name_or_buffer, mode)
  File "/work/cvcs_2023_group23/environments/cvcs_env/lib/python3.9/site-packages/torch/serialization.py", line 252, in __init__
    super().__init__(open(name, mode))
FileNotFoundError: [Errno 2] No such file or directory: '/work/cvcs_2023_group23/ObjectDescriptionSupermarket-CVCS-UniMoRe/checkpoints/frcnn/checkpoint.pth'
Traceback (most recent call last):
  File "/work/cvcs_2023_group23/ObjectDescriptionSupermarket-CVCS-UniMoRe/evaluate.py", line 318, in <module>
    main()
  File "/work/cvcs_2023_group23/ObjectDescriptionSupermarket-CVCS-UniMoRe/evaluate.py", line 297, in main
    model = load_model(
  File "/work/cvcs_2023_group23/ObjectDescriptionSupermarket-CVCS-UniMoRe/evaluate.py", line 76, in load_model
    checkpoint = torch.load(checkpoint_path)
  File "/work/cvcs_2023_group23/environments/cvcs_env/lib/python3.9/site-packages/torch/serialization.py", line 791, in load
    with _open_file_like(f, 'rb') as opened_file:
  File "/work/cvcs_2023_group23/environments/cvcs_env/lib/python3.9/site-packages/torch/serialization.py", line 271, in _open_file_like
    return _open_file(name_or_buffer, mode)
  File "/work/cvcs_2023_group23/environments/cvcs_env/lib/python3.9/site-packages/torch/serialization.py", line 252, in __init__
    super().__init__(open(name, mode))
FileNotFoundError: [Errno 2] No such file or directory: '/work/cvcs_2023_group23/ObjectDescriptionSupermarket-CVCS-UniMoRe/checkpoints/frcnn/checkpoint.pth'
ERROR:torch.distributed.elastic.multiprocessing.api:failed (exitcode: 1) local_rank: 0 (pid: 3606978) of binary: /work/cvcs_2023_group23/environments/cvcs_env/bin/python
Traceback (most recent call last):
  File "/usr/local/anaconda3/lib/python3.9/runpy.py", line 197, in _run_module_as_main
    return _run_code(code, main_globals, None,
  File "/usr/local/anaconda3/lib/python3.9/runpy.py", line 87, in _run_code
    exec(code, run_globals)
  File "/work/cvcs_2023_group23/environments/cvcs_env/lib/python3.9/site-packages/torch/distributed/run.py", line 798, in <module>
    main()
  File "/work/cvcs_2023_group23/environments/cvcs_env/lib/python3.9/site-packages/torch/distributed/elastic/multiprocessing/errors/__init__.py", line 346, in wrapper
    return f(*args, **kwargs)
  File "/work/cvcs_2023_group23/environments/cvcs_env/lib/python3.9/site-packages/torch/distributed/run.py", line 794, in main
    run(args)
  File "/work/cvcs_2023_group23/environments/cvcs_env/lib/python3.9/site-packages/torch/distributed/run.py", line 785, in run
    elastic_launch(
  File "/work/cvcs_2023_group23/environments/cvcs_env/lib/python3.9/site-packages/torch/distributed/launcher/api.py", line 134, in __call__
    return launch_agent(self._config, self._entrypoint, list(args))
  File "/work/cvcs_2023_group23/environments/cvcs_env/lib/python3.9/site-packages/torch/distributed/launcher/api.py", line 250, in launch_agent
    raise ChildFailedError(
torch.distributed.elastic.multiprocessing.errors.ChildFailedError: 
============================================================
evaluate.py FAILED
------------------------------------------------------------
Failures:
[1]:
  time      : 2024-01-20_20:36:53
  host      : aimagelab-srv-00.ing.unimore.it
  rank      : 1 (local_rank: 1)
  exitcode  : 1 (pid: 3606979)
  error_file: <N/A>
  traceback : To enable traceback see: https://pytorch.org/docs/stable/elastic/errors.html
[2]:
  time      : 2024-01-20_20:36:53
  host      : aimagelab-srv-00.ing.unimore.it
  rank      : 2 (local_rank: 2)
  exitcode  : 1 (pid: 3606980)
  error_file: <N/A>
  traceback : To enable traceback see: https://pytorch.org/docs/stable/elastic/errors.html
------------------------------------------------------------
Root Cause (first observed failure):
[0]:
  time      : 2024-01-20_20:36:53
  host      : aimagelab-srv-00.ing.unimore.it
  rank      : 0 (local_rank: 0)
  exitcode  : 1 (pid: 3606978)
  error_file: <N/A>
  traceback : To enable traceback see: https://pytorch.org/docs/stable/elastic/errors.html
============================================================
