WARNING:__main__:
*****************************************
Setting OMP_NUM_THREADS environment variable for each process to be 1 in default, to avoid your system being overloaded, please further tune the variable for optimal performance in your application as needed. 
*****************************************
/work/cvcs_2023_group23/environments/cvcs_env/lib/python3.9/site-packages/torchvision/models/_utils.py:208: UserWarning: The parameter 'pretrained' is deprecated since 0.13 and may be removed in the future, please use 'weights' instead.
  warnings.warn(
/work/cvcs_2023_group23/environments/cvcs_env/lib/python3.9/site-packages/torchvision/models/_utils.py:208: UserWarning: The parameter 'pretrained' is deprecated since 0.13 and may be removed in the future, please use 'weights' instead.
  warnings.warn(
/work/cvcs_2023_group23/environments/cvcs_env/lib/python3.9/site-packages/torchvision/models/_utils.py:223: UserWarning: Arguments other than a weight enum or `None` for 'weights' are deprecated since 0.13 and may be removed in the future. The current behavior is equivalent to passing `weights=FasterRCNN_ResNet50_FPN_Weights.COCO_V1`. You can also use `weights=FasterRCNN_ResNet50_FPN_Weights.DEFAULT` to get the most up-to-date weights.
  warnings.warn(msg)
/work/cvcs_2023_group23/environments/cvcs_env/lib/python3.9/site-packages/torchvision/models/_utils.py:223: UserWarning: Arguments other than a weight enum or `None` for 'weights' are deprecated since 0.13 and may be removed in the future. The current behavior is equivalent to passing `weights=FasterRCNN_ResNet50_FPN_Weights.COCO_V1`. You can also use `weights=FasterRCNN_ResNet50_FPN_Weights.DEFAULT` to get the most up-to-date weights.
  warnings.warn(msg)
Traceback (most recent call last):
  File "/work/cvcs_2023_group23/ObjectDescriptionSupermarket-CVCS-UniMoRe/train.py", line 358, in <module>
    main()
  File "/work/cvcs_2023_group23/ObjectDescriptionSupermarket-CVCS-UniMoRe/train.py", line 347, in main
    val_loss = validate(model, val_dataloader, device, epoch, writer)
  File "/work/cvcs_2023_group23/ObjectDescriptionSupermarket-CVCS-UniMoRe/train.py", line 204, in validate
    outputs = model(images)
  File "/work/cvcs_2023_group23/environments/cvcs_env/lib/python3.9/site-packages/torch/nn/modules/module.py", line 1501, in _call_impl
    return forward_call(*args, **kwargs)
  File "/work/cvcs_2023_group23/environments/cvcs_env/lib/python3.9/site-packages/torch/nn/parallel/distributed.py", line 1156, in forward
    output = self._run_ddp_forward(*inputs, **kwargs)
  File "/work/cvcs_2023_group23/environments/cvcs_env/lib/python3.9/site-packages/torch/nn/parallel/distributed.py", line 1110, in _run_ddp_forward
    return module_to_run(*inputs[0], **kwargs[0])  # type: ignore[index]
  File "/work/cvcs_2023_group23/environments/cvcs_env/lib/python3.9/site-packages/torch/nn/modules/module.py", line 1501, in _call_impl
    return forward_call(*args, **kwargs)
  File "/work/cvcs_2023_group23/environments/cvcs_env/lib/python3.9/site-packages/torchvision/models/detection/generalized_rcnn.py", line 101, in forward
    features = self.backbone(images.tensors)
  File "/work/cvcs_2023_group23/environments/cvcs_env/lib/python3.9/site-packages/torch/nn/modules/module.py", line 1501, in _call_impl
    return forward_call(*args, **kwargs)
  File "/work/cvcs_2023_group23/environments/cvcs_env/lib/python3.9/site-packages/torchvision/models/detection/backbone_utils.py", line 58, in forward
    x = self.fpn(x)
  File "/work/cvcs_2023_group23/environments/cvcs_env/lib/python3.9/site-packages/torch/nn/modules/module.py", line 1501, in _call_impl
    return forward_call(*args, **kwargs)
  File "/work/cvcs_2023_group23/environments/cvcs_env/lib/python3.9/site-packages/torchvision/ops/feature_pyramid_network.py", line 195, in forward
    last_inner = inner_lateral + inner_top_down
torch.cuda.OutOfMemoryError: CUDA out of memory. Tried to allocate 470.00 MiB (GPU 0; 11.92 GiB total capacity; 10.34 GiB already allocated; 58.69 MiB free; 11.39 GiB reserved in total by PyTorch) If reserved memory is >> allocated memory try setting max_split_size_mb to avoid fragmentation.  See documentation for Memory Management and PYTORCH_CUDA_ALLOC_CONF
Traceback (most recent call last):
  File "/work/cvcs_2023_group23/ObjectDescriptionSupermarket-CVCS-UniMoRe/train.py", line 358, in <module>
    main()
  File "/work/cvcs_2023_group23/ObjectDescriptionSupermarket-CVCS-UniMoRe/train.py", line 347, in main
    val_loss = validate(model, val_dataloader, device, epoch, writer)
  File "/work/cvcs_2023_group23/ObjectDescriptionSupermarket-CVCS-UniMoRe/train.py", line 204, in validate
    outputs = model(images)
  File "/work/cvcs_2023_group23/environments/cvcs_env/lib/python3.9/site-packages/torch/nn/modules/module.py", line 1501, in _call_impl
    return forward_call(*args, **kwargs)
  File "/work/cvcs_2023_group23/environments/cvcs_env/lib/python3.9/site-packages/torch/nn/parallel/distributed.py", line 1156, in forward
    output = self._run_ddp_forward(*inputs, **kwargs)
  File "/work/cvcs_2023_group23/environments/cvcs_env/lib/python3.9/site-packages/torch/nn/parallel/distributed.py", line 1110, in _run_ddp_forward
    return module_to_run(*inputs[0], **kwargs[0])  # type: ignore[index]
  File "/work/cvcs_2023_group23/environments/cvcs_env/lib/python3.9/site-packages/torch/nn/modules/module.py", line 1501, in _call_impl
    return forward_call(*args, **kwargs)
  File "/work/cvcs_2023_group23/environments/cvcs_env/lib/python3.9/site-packages/torchvision/models/detection/generalized_rcnn.py", line 101, in forward
    features = self.backbone(images.tensors)
  File "/work/cvcs_2023_group23/environments/cvcs_env/lib/python3.9/site-packages/torch/nn/modules/module.py", line 1501, in _call_impl
    return forward_call(*args, **kwargs)
  File "/work/cvcs_2023_group23/environments/cvcs_env/lib/python3.9/site-packages/torchvision/models/detection/backbone_utils.py", line 58, in forward
    x = self.fpn(x)
  File "/work/cvcs_2023_group23/environments/cvcs_env/lib/python3.9/site-packages/torch/nn/modules/module.py", line 1501, in _call_impl
    return forward_call(*args, **kwargs)
  File "/work/cvcs_2023_group23/environments/cvcs_env/lib/python3.9/site-packages/torchvision/ops/feature_pyramid_network.py", line 196, in forward
    results.insert(0, self.get_result_from_layer_blocks(last_inner, idx))
  File "/work/cvcs_2023_group23/environments/cvcs_env/lib/python3.9/site-packages/torchvision/ops/feature_pyramid_network.py", line 169, in get_result_from_layer_blocks
    out = module(x)
  File "/work/cvcs_2023_group23/environments/cvcs_env/lib/python3.9/site-packages/torch/nn/modules/module.py", line 1501, in _call_impl
    return forward_call(*args, **kwargs)
  File "/work/cvcs_2023_group23/environments/cvcs_env/lib/python3.9/site-packages/torch/nn/modules/container.py", line 217, in forward
    input = module(input)
  File "/work/cvcs_2023_group23/environments/cvcs_env/lib/python3.9/site-packages/torch/nn/modules/module.py", line 1501, in _call_impl
    return forward_call(*args, **kwargs)
  File "/work/cvcs_2023_group23/environments/cvcs_env/lib/python3.9/site-packages/torch/nn/modules/conv.py", line 463, in forward
    return self._conv_forward(input, self.weight, self.bias)
  File "/work/cvcs_2023_group23/environments/cvcs_env/lib/python3.9/site-packages/torch/nn/modules/conv.py", line 459, in _conv_forward
    return F.conv2d(input, weight, bias, self.stride,
torch.cuda.OutOfMemoryError: CUDA out of memory. Tried to allocate 470.00 MiB (GPU 1; 11.92 GiB total capacity; 10.80 GiB already allocated; 66.69 MiB free; 11.38 GiB reserved in total by PyTorch) If reserved memory is >> allocated memory try setting max_split_size_mb to avoid fragmentation.  See documentation for Memory Management and PYTORCH_CUDA_ALLOC_CONF
ERROR:torch.distributed.elastic.multiprocessing.api:failed (exitcode: 1) local_rank: 0 (pid: 3734547) of binary: /work/cvcs_2023_group23/environments/cvcs_env/bin/python
Traceback (most recent call last):
  File "/usr/local/anaconda3/lib/python3.9/runpy.py", line 197, in _run_module_as_main
    return _run_code(code, main_globals, None,
  File "/usr/local/anaconda3/lib/python3.9/runpy.py", line 87, in _run_code
    exec(code, run_globals)
  File "/work/cvcs_2023_group23/environments/cvcs_env/lib/python3.9/site-packages/torch/distributed/run.py", line 798, in <module>
    main()
  File "/work/cvcs_2023_group23/environments/cvcs_env/lib/python3.9/site-packages/torch/distributed/elastic/multiprocessing/errors/__init__.py", line 346, in wrapper
    return f(*args, **kwargs)
  File "/work/cvcs_2023_group23/environments/cvcs_env/lib/python3.9/site-packages/torch/distributed/run.py", line 794, in main
    run(args)
  File "/work/cvcs_2023_group23/environments/cvcs_env/lib/python3.9/site-packages/torch/distributed/run.py", line 785, in run
    elastic_launch(
  File "/work/cvcs_2023_group23/environments/cvcs_env/lib/python3.9/site-packages/torch/distributed/launcher/api.py", line 134, in __call__
    return launch_agent(self._config, self._entrypoint, list(args))
  File "/work/cvcs_2023_group23/environments/cvcs_env/lib/python3.9/site-packages/torch/distributed/launcher/api.py", line 250, in launch_agent
    raise ChildFailedError(
torch.distributed.elastic.multiprocessing.errors.ChildFailedError: 
============================================================
train.py FAILED
------------------------------------------------------------
Failures:
[1]:
  time      : 2024-01-20_21:29:05
  host      : aimagelab-srv-00.ing.unimore.it
  rank      : 1 (local_rank: 1)
  exitcode  : 1 (pid: 3734548)
  error_file: <N/A>
  traceback : To enable traceback see: https://pytorch.org/docs/stable/elastic/errors.html
------------------------------------------------------------
Root Cause (first observed failure):
[0]:
  time      : 2024-01-20_21:29:05
  host      : aimagelab-srv-00.ing.unimore.it
  rank      : 0 (local_rank: 0)
  exitcode  : 1 (pid: 3734547)
  error_file: <N/A>
  traceback : To enable traceback see: https://pytorch.org/docs/stable/elastic/errors.html
============================================================
WARNING:__main__:
*****************************************
Setting OMP_NUM_THREADS environment variable for each process to be 1 in default, to avoid your system being overloaded, please further tune the variable for optimal performance in your application as needed. 
*****************************************
/work/cvcs_2023_group23/environments/cvcs_env/lib/python3.9/site-packages/torchvision/models/_utils.py:208: UserWarning: The parameter 'pretrained' is deprecated since 0.13 and may be removed in the future, please use 'weights' instead.
  warnings.warn(
/work/cvcs_2023_group23/environments/cvcs_env/lib/python3.9/site-packages/torchvision/models/_utils.py:223: UserWarning: Arguments other than a weight enum or `None` for 'weights' are deprecated since 0.13 and may be removed in the future. The current behavior is equivalent to passing `weights=FasterRCNN_ResNet50_FPN_Weights.COCO_V1`. You can also use `weights=FasterRCNN_ResNet50_FPN_Weights.DEFAULT` to get the most up-to-date weights.
  warnings.warn(msg)
/work/cvcs_2023_group23/environments/cvcs_env/lib/python3.9/site-packages/torchvision/models/_utils.py:208: UserWarning: The parameter 'pretrained' is deprecated since 0.13 and may be removed in the future, please use 'weights' instead.
  warnings.warn(
/work/cvcs_2023_group23/environments/cvcs_env/lib/python3.9/site-packages/torchvision/models/_utils.py:223: UserWarning: Arguments other than a weight enum or `None` for 'weights' are deprecated since 0.13 and may be removed in the future. The current behavior is equivalent to passing `weights=FasterRCNN_ResNet50_FPN_Weights.COCO_V1`. You can also use `weights=FasterRCNN_ResNet50_FPN_Weights.DEFAULT` to get the most up-to-date weights.
  warnings.warn(msg)
Traceback (most recent call last):
  File "/work/cvcs_2023_group23/ObjectDescriptionSupermarket-CVCS-UniMoRe/evaluate.py", line 318, in <module>
    main()
  File "/work/cvcs_2023_group23/ObjectDescriptionSupermarket-CVCS-UniMoRe/evaluate.py", line 297, in main
    model = load_model(
  File "/work/cvcs_2023_group23/ObjectDescriptionSupermarket-CVCS-UniMoRe/evaluate.py", line 76, in load_model
    checkpoint = torch.load(checkpoint_path)
  File "/work/cvcs_2023_group23/environments/cvcs_env/lib/python3.9/site-packages/torch/serialization.py", line 791, in load
    with _open_file_like(f, 'rb') as opened_file:
  File "/work/cvcs_2023_group23/environments/cvcs_env/lib/python3.9/site-packages/torch/serialization.py", line 271, in _open_file_like
    return _open_file(name_or_buffer, mode)
  File "/work/cvcs_2023_group23/environments/cvcs_env/lib/python3.9/site-packages/torch/serialization.py", line 252, in __init__
    super().__init__(open(name, mode))
FileNotFoundError: [Errno 2] No such file or directory: '/work/cvcs_2023_group23/ObjectDescriptionSupermarket-CVCS-UniMoRe/checkpoints/frcnn/checkpoint.pth'
Traceback (most recent call last):
  File "/work/cvcs_2023_group23/ObjectDescriptionSupermarket-CVCS-UniMoRe/evaluate.py", line 318, in <module>
    main()
  File "/work/cvcs_2023_group23/ObjectDescriptionSupermarket-CVCS-UniMoRe/evaluate.py", line 297, in main
    model = load_model(
  File "/work/cvcs_2023_group23/ObjectDescriptionSupermarket-CVCS-UniMoRe/evaluate.py", line 76, in load_model
    checkpoint = torch.load(checkpoint_path)
  File "/work/cvcs_2023_group23/environments/cvcs_env/lib/python3.9/site-packages/torch/serialization.py", line 791, in load
    with _open_file_like(f, 'rb') as opened_file:
  File "/work/cvcs_2023_group23/environments/cvcs_env/lib/python3.9/site-packages/torch/serialization.py", line 271, in _open_file_like
    return _open_file(name_or_buffer, mode)
  File "/work/cvcs_2023_group23/environments/cvcs_env/lib/python3.9/site-packages/torch/serialization.py", line 252, in __init__
    super().__init__(open(name, mode))
FileNotFoundError: [Errno 2] No such file or directory: '/work/cvcs_2023_group23/ObjectDescriptionSupermarket-CVCS-UniMoRe/checkpoints/frcnn/checkpoint.pth'
ERROR:torch.distributed.elastic.multiprocessing.api:failed (exitcode: 1) local_rank: 0 (pid: 3935948) of binary: /work/cvcs_2023_group23/environments/cvcs_env/bin/python
Traceback (most recent call last):
  File "/usr/local/anaconda3/lib/python3.9/runpy.py", line 197, in _run_module_as_main
    return _run_code(code, main_globals, None,
  File "/usr/local/anaconda3/lib/python3.9/runpy.py", line 87, in _run_code
    exec(code, run_globals)
  File "/work/cvcs_2023_group23/environments/cvcs_env/lib/python3.9/site-packages/torch/distributed/run.py", line 798, in <module>
    main()
  File "/work/cvcs_2023_group23/environments/cvcs_env/lib/python3.9/site-packages/torch/distributed/elastic/multiprocessing/errors/__init__.py", line 346, in wrapper
    return f(*args, **kwargs)
  File "/work/cvcs_2023_group23/environments/cvcs_env/lib/python3.9/site-packages/torch/distributed/run.py", line 794, in main
    run(args)
  File "/work/cvcs_2023_group23/environments/cvcs_env/lib/python3.9/site-packages/torch/distributed/run.py", line 785, in run
    elastic_launch(
  File "/work/cvcs_2023_group23/environments/cvcs_env/lib/python3.9/site-packages/torch/distributed/launcher/api.py", line 134, in __call__
    return launch_agent(self._config, self._entrypoint, list(args))
  File "/work/cvcs_2023_group23/environments/cvcs_env/lib/python3.9/site-packages/torch/distributed/launcher/api.py", line 250, in launch_agent
    raise ChildFailedError(
torch.distributed.elastic.multiprocessing.errors.ChildFailedError: 
============================================================
evaluate.py FAILED
------------------------------------------------------------
Failures:
[1]:
  time      : 2024-01-20_21:29:35
  host      : aimagelab-srv-00.ing.unimore.it
  rank      : 1 (local_rank: 1)
  exitcode  : 1 (pid: 3935949)
  error_file: <N/A>
  traceback : To enable traceback see: https://pytorch.org/docs/stable/elastic/errors.html
------------------------------------------------------------
Root Cause (first observed failure):
[0]:
  time      : 2024-01-20_21:29:35
  host      : aimagelab-srv-00.ing.unimore.it
  rank      : 0 (local_rank: 0)
  exitcode  : 1 (pid: 3935948)
  error_file: <N/A>
  traceback : To enable traceback see: https://pytorch.org/docs/stable/elastic/errors.html
============================================================
