WARNING:__main__:
*****************************************
Setting OMP_NUM_THREADS environment variable for each process to be 1 in default, to avoid your system being overloaded, please further tune the variable for optimal performance in your application as needed. 
*****************************************
Traceback (most recent call last):
  File "/work/cvcs_2023_group23/ObjectDescriptionSupermarket-CVCS-UniMoRe/train.py", line 356, in <module>
    main()
  File "/work/cvcs_2023_group23/ObjectDescriptionSupermarket-CVCS-UniMoRe/train.py", line 269, in main
    torch.cuda.set_device(local_rank)
  File "/work/cvcs_2023_group23/environments/cvcs_env/lib/python3.9/site-packages/torch/cuda/__init__.py", line 350, in set_device
    torch._C._cuda_setDevice(device)
RuntimeError: CUDA error: invalid device ordinal
CUDA kernel errors might be asynchronously reported at some other API call, so the stacktrace below might be incorrect.
For debugging consider passing CUDA_LAUNCH_BLOCKING=1.
Compile with `TORCH_USE_CUDA_DSA` to enable device-side assertions.

WARNING:torch.distributed.elastic.multiprocessing.api:Sending process 3613113 closing signal SIGTERM
WARNING:torch.distributed.elastic.multiprocessing.api:Sending process 3613124 closing signal SIGTERM
ERROR:torch.distributed.elastic.multiprocessing.api:failed (exitcode: 1) local_rank: 2 (pid: 3613126) of binary: /work/cvcs_2023_group23/environments/cvcs_env/bin/python
Traceback (most recent call last):
  File "/usr/local/anaconda3/lib/python3.9/runpy.py", line 197, in _run_module_as_main
    return _run_code(code, main_globals, None,
  File "/usr/local/anaconda3/lib/python3.9/runpy.py", line 87, in _run_code
    exec(code, run_globals)
  File "/work/cvcs_2023_group23/environments/cvcs_env/lib/python3.9/site-packages/torch/distributed/run.py", line 798, in <module>
    main()
  File "/work/cvcs_2023_group23/environments/cvcs_env/lib/python3.9/site-packages/torch/distributed/elastic/multiprocessing/errors/__init__.py", line 346, in wrapper
    return f(*args, **kwargs)
  File "/work/cvcs_2023_group23/environments/cvcs_env/lib/python3.9/site-packages/torch/distributed/run.py", line 794, in main
    run(args)
  File "/work/cvcs_2023_group23/environments/cvcs_env/lib/python3.9/site-packages/torch/distributed/run.py", line 785, in run
    elastic_launch(
  File "/work/cvcs_2023_group23/environments/cvcs_env/lib/python3.9/site-packages/torch/distributed/launcher/api.py", line 134, in __call__
    return launch_agent(self._config, self._entrypoint, list(args))
  File "/work/cvcs_2023_group23/environments/cvcs_env/lib/python3.9/site-packages/torch/distributed/launcher/api.py", line 250, in launch_agent
    raise ChildFailedError(
torch.distributed.elastic.multiprocessing.errors.ChildFailedError: 
============================================================
train.py FAILED
------------------------------------------------------------
Failures:
  <NO_OTHER_FAILURES>
------------------------------------------------------------
Root Cause (first observed failure):
[0]:
  time      : 2024-01-20_20:37:46
  host      : aimagelab-srv-00.ing.unimore.it
  rank      : 2 (local_rank: 2)
  exitcode  : 1 (pid: 3613126)
  error_file: <N/A>
  traceback : To enable traceback see: https://pytorch.org/docs/stable/elastic/errors.html
============================================================
WARNING:__main__:
*****************************************
Setting OMP_NUM_THREADS environment variable for each process to be 1 in default, to avoid your system being overloaded, please further tune the variable for optimal performance in your application as needed. 
*****************************************
Traceback (most recent call last):
  File "/work/cvcs_2023_group23/ObjectDescriptionSupermarket-CVCS-UniMoRe/evaluate.py", line 318, in <module>
    main()
  File "/work/cvcs_2023_group23/ObjectDescriptionSupermarket-CVCS-UniMoRe/evaluate.py", line 295, in main
    torch.cuda.set_device(local_rank)
  File "/work/cvcs_2023_group23/environments/cvcs_env/lib/python3.9/site-packages/torch/cuda/__init__.py", line 350, in set_device
    torch._C._cuda_setDevice(device)
RuntimeError: CUDA error: invalid device ordinal
CUDA kernel errors might be asynchronously reported at some other API call, so the stacktrace below might be incorrect.
For debugging consider passing CUDA_LAUNCH_BLOCKING=1.
Compile with `TORCH_USE_CUDA_DSA` to enable device-side assertions.

WARNING:torch.distributed.elastic.multiprocessing.api:Sending process 3615252 closing signal SIGTERM
WARNING:torch.distributed.elastic.multiprocessing.api:Sending process 3615257 closing signal SIGTERM
ERROR:torch.distributed.elastic.multiprocessing.api:failed (exitcode: 1) local_rank: 2 (pid: 3615258) of binary: /work/cvcs_2023_group23/environments/cvcs_env/bin/python
Traceback (most recent call last):
  File "/usr/local/anaconda3/lib/python3.9/runpy.py", line 197, in _run_module_as_main
    return _run_code(code, main_globals, None,
  File "/usr/local/anaconda3/lib/python3.9/runpy.py", line 87, in _run_code
    exec(code, run_globals)
  File "/work/cvcs_2023_group23/environments/cvcs_env/lib/python3.9/site-packages/torch/distributed/run.py", line 798, in <module>
    main()
  File "/work/cvcs_2023_group23/environments/cvcs_env/lib/python3.9/site-packages/torch/distributed/elastic/multiprocessing/errors/__init__.py", line 346, in wrapper
    return f(*args, **kwargs)
  File "/work/cvcs_2023_group23/environments/cvcs_env/lib/python3.9/site-packages/torch/distributed/run.py", line 794, in main
    run(args)
  File "/work/cvcs_2023_group23/environments/cvcs_env/lib/python3.9/site-packages/torch/distributed/run.py", line 785, in run
    elastic_launch(
  File "/work/cvcs_2023_group23/environments/cvcs_env/lib/python3.9/site-packages/torch/distributed/launcher/api.py", line 134, in __call__
    return launch_agent(self._config, self._entrypoint, list(args))
  File "/work/cvcs_2023_group23/environments/cvcs_env/lib/python3.9/site-packages/torch/distributed/launcher/api.py", line 250, in launch_agent
    raise ChildFailedError(
torch.distributed.elastic.multiprocessing.errors.ChildFailedError: 
============================================================
evaluate.py FAILED
------------------------------------------------------------
Failures:
  <NO_OTHER_FAILURES>
------------------------------------------------------------
Root Cause (first observed failure):
[0]:
  time      : 2024-01-20_20:38:12
  host      : aimagelab-srv-00.ing.unimore.it
  rank      : 2 (local_rank: 2)
  exitcode  : 1 (pid: 3615258)
  error_file: <N/A>
  traceback : To enable traceback see: https://pytorch.org/docs/stable/elastic/errors.html
============================================================
